<?xml version="1.0" encoding="utf-8"?>
<!-- =================================================================================== -->
<!-- |    This document was autogenerated by xacro from gripper_only.urdf.xacro        | -->
<!-- |    EDITING THIS FILE BY HAND IS NOT RECOMMENDED                                 | -->
<!-- =================================================================================== -->
<robot name="ur5e">
  <gazebo>
    <plugin filename="libgazebo_ros_control.so" name="ros_control">
      <!--robotNamespace>/</robotNamespace-->
      <!--robotSimType>gazebo_ros_control/DefaultRobotHWSim</robotSimType-->
    </plugin>
    <!--
    <plugin name="gazebo_ros_power_monitor_controller" filename="libgazebo_ros_power_monitor.so">
      <alwaysOn>true</alwaysOn>
      <updateRate>1.0</updateRate>
      <timeout>5</timeout>
      <powerStateTopic>power_state</powerStateTopic>
      <powerStateRate>10.0</powerStateRate>
      <fullChargeCapacity>87.78</fullChargeCapacity>     
      <dischargeRate>-474</dischargeRate>
      <chargeRate>525</chargeRate>
      <dischargeVoltage>15.52</dischargeVoltage>
      <chargeVoltage>16.41</chargeVoltage>
    </plugin>
-->
  </gazebo>
  <link name="world"/>
  <!-- Adding table to the world -->
  <link name="table">
    <origin rpy="0 0 0" xyz="0.0 0.0 0.0"/>
    <inertial>
      <mass value="5"/>
      <origin xyz="0 0 0"/>
      <inertia ixx="1" ixy="0.0" ixz="0.0" iyy="1" iyz="0.0" izz="1"/>
    </inertial>
    <visual>
      <geometry>
        <mesh filename="package://ur_e_description/meshes/table/visual/table.dae"/>
      </geometry>
    </visual>
    <collision>
      <geometry>
        <mesh filename="package://ur_e_description/meshes/table/collision/table.obj"/>
      </geometry>
    </collision>
  </link>
  <joint name="world_joint" type="fixed">
    <parent link="world"/>
    <child link="table"/>
    <origin rpy="0.0 0.0 -1.57" xyz="0.0 0.0 -0.005"/>
  </joint>
  <!-- fixing robot base link to the table -->
  <link name="tool0"/>
  <joint name="world-tool0_floating_joint" type="floating">
    <origin rpy="-1.57079632679 0 0" xyz="0 0.1 0"/>
    <parent link="world"/>
    <child link="tool0"/>
  </joint>

  <joint name="robotiq_ur_coupler_coupler_joint" type="fixed">
    <!-- total height of coupler, minus the depth of robot end-effector shape and the gripper small depth-->
    <origin rpy="0 0 0" xyz="0 0 0.0075"/>
    <parent link="tool0"/>
    <child link="robotiq_ur_coupler"/>
  </joint>
  <link name="robotiq_ur_coupler">
    <visual>
      <origin rpy="0 0 0" xyz="0 0 -0.005465"/>
      <geometry>
        <!-- only the visible part of the coupler -->
        <cylinder length="0.0139" radius="0.0375"/>
      </geometry>
      <material name="dark_grey">
        <color rgba="0.05 0.05 0.05 1"/>
      </material>
    </visual>
    <collision>
      <origin rpy="0 0 0" xyz="0 0 0"/>
      <geometry>
        <cylinder length="0.0135" radius="0.0375"/>
      </geometry>
    </collision>
    <inertial>
      <mass value="0.3"/>
      <origin xyz="0 0 0.00695"/>
      <inertia ixx="0.110299" ixy="0" ixz="0" iyy="0.110299" iyz="0" izz="0.2109375"/>
    </inertial>
  </link>
  <!-- the ee link of gripper -->
  <joint name="robotiq_ur_coupler_robotiq_2f_85_ee_joint" type="fixed">
    <origin rpy="0 0 0" xyz="0 0 0.1493"/>
    <parent link="robotiq_2f_85_base"/>
    <child link="robotiq_2f_85_ee_link"/>
  </joint>
  <link name="robotiq_2f_85_ee_link"/>
  <!-- base -->
  <joint name="robotiq_ur_coupler_robotiq_2f_85_base_joint" type="fixed">
    <origin rpy="0 0 1.57079632679" xyz="0 0 0"/>
    <parent link="robotiq_ur_coupler"/>
    <child link="robotiq_2f_85_base"/>
  </joint>
  <link name="robotiq_2f_85_base">
    <inertial>
      <mass value="0.5"/>
      <origin xyz="0 0 0.0075"/>
      <inertia ixx="0.284375" ixy="0" ixz="0" iyy="0.284375" iyz="0" izz="0.4"/>
    </inertial>
    <visual>
      <origin rpy="0 -1.5708 0" xyz="0 0 0"/>
      <geometry>
        <mesh filename="package://robotiq_2f_85_gripper_visualization/meshes/visual/base.dae"/>
      </geometry>
    </visual>
    <collision>
      <origin rpy="0 0 0" xyz="0 0 0.015"/>
      <geometry>
        <cylinder length="0.045" radius="0.04"/>
      </geometry>
    </collision>
    <collision>
      <origin rpy="0 0 0" xyz="0 0 0.06"/>
      <geometry>
        <box size="0.03 0.03 0.06"/>
      </geometry>
    </collision>
  </link>
  <!-- right finger -->
  <joint name="robotiq_2f_85_right_driver_joint" type="revolute">
    <origin rpy="0 0 0" xyz="0 0.0306011 0.054904"/>
    <parent link="robotiq_2f_85_base"/>
    <child link="robotiq_2f_85_right_driver"/>
    <axis xyz="1 0 0"/>
    <limit effort="60" lower="0.0" upper="0.872664444444" velocity="1.91986177778"/>
  </joint>
  <link name="robotiq_2f_85_right_driver">
    <inertial>
      <mass value="0.1"/>
      <origin rpy="0 0 0" xyz="0 0.02 0"/>
      <inertia ixx="0.0166666666667" ixy="0" ixz="0" iyy="0.00666666666667" iyz="0" izz="0.0166666666667"/>
    </inertial>
    <visual>
      <geometry>
        <mesh filename="package://robotiq_2f_85_gripper_visualization/meshes/visual/driver.dae" scale="0.001 0.001 0.001"/>
      </geometry>
    </visual>
    <collision>
      <origin rpy="-0.1 0 0" xyz="0 0.01 0"/>
      <geometry>
        <box size="0.002 0.004 0.002"/>
      </geometry>
    </collision>
  </link>
  <joint name="robotiq_2f_85_right_coupler_joint" type="fixed">
    <origin rpy="0 0 0" xyz="0 0.0315 -0.0041"/>
    <parent link="robotiq_2f_85_right_driver"/>
    <child link="robotiq_2f_85_right_coupler"/>
  </joint>
  <link name="robotiq_2f_85_right_coupler">
    <inertial>
      <mass value="0.1"/>
      <origin rpy="-1.7 0 0" xyz="0 0.0 0.025"/>
      <inertia ixx="0.0385416666667" ixy="0" ixz="0" iyy="0.0108333333333" iyz="0" izz="0.0427083333333"/>
    </inertial>
    <visual>
      <geometry>
        <mesh filename="package://robotiq_2f_85_gripper_visualization/meshes/visual/coupler.dae" scale="0.001 0.001 0.001"/>
      </geometry>
    </visual>
    <collision>
      <origin rpy="-1.7 0 0" xyz="0 0.0 0.025"/>
      <geometry>
        <box size="0.03 0.065 0.02"/>
      </geometry>
    </collision>
  </link>
  <joint name="robotiq_2f_85_right_follower_joint" type="revolute">
    <origin rpy="0 0 0" xyz="0 0.0061 0.0471"/>
    <parent link="robotiq_2f_85_right_coupler"/>
    <child link="robotiq_2f_85_right_follower"/>
    <axis xyz="1 0 0"/>
    <limit effort="176" lower="-2.96705911111" upper="2.96705911111" velocity="1.91986177778"/>
    <mimic joint="robotiq_2f_85_right_driver_joint" multiplier="-1"/>
  </joint>
  <link name="robotiq_2f_85_right_follower">
    <inertial>
      <mass value="0.1"/>
      <origin xyz="0 -0.018 0.022"/>
      <inertia ixx="0.021075" ixy="0" ixz="0" iyy="0.0225333333333" iyz="0" izz="0.00520833333333"/>
    </inertial>
    <visual>
      <geometry>
        <mesh filename="package://robotiq_2f_85_gripper_visualization/meshes/visual/follower.dae" scale="0.001 0.001 0.001"/>
      </geometry>
    </visual>
    <collision>
      <origin rpy="0 0 0" xyz="0 -0.01 0.022"/>
      <geometry>
        <box size="0.002 0.0015 0.0048"/>
      </geometry>
    </collision>
  </link>
  <joint name="robotiq_2f_85_right_pad_joint" type="revolute">
    <parent link="robotiq_2f_85_right_follower"/>
    <child link="robotiq_2f_85_right_pad"/>
    <axis xyz="0 0 1"/>
    <limit effort="200" lower="0" upper="0" velocity="0"/>
    <mimic joint="robotiq_2f_85_right_driver_joint" multiplier="0"/>
  </joint>
  <link name="robotiq_2f_85_right_pad">
    <inertial>
      <mass value="0.1"/>
      <origin xyz="0 -0.022 0.031"/>
      <inertia ixx="0.0113333333333" ixy="0" ixz="0" iyy="0.0141333333333" iyz="0" izz="0.00386666666667"/>
    </inertial>
    <visual>
      <geometry>
        <mesh filename="package://robotiq_2f_85_gripper_visualization/meshes/visual/pad.dae" scale="0.001 0.001 0.001"/>
      </geometry>
    </visual>
    <collision>
      <origin rpy="0 0 0" xyz="0 -0.022 0.031"/>
      <geometry>
        <box size="0.02 0.008 0.036"/>
      </geometry>
    </collision>
  </link>
  <joint name="robotiq_2f_85_right_spring_link_joint" type="revolute">
    <origin rpy="0 0 0" xyz="0 0.012 0.0614"/>
    <parent link="robotiq_2f_85_base"/>
    <child link="robotiq_2f_85_right_spring_link"/>
    <axis xyz="1 0 0"/>
    <limit effort="176" lower="-2.96705911111" upper="2.96705911111" velocity="1.91986177778"/>
    <mimic joint="robotiq_2f_85_right_driver_joint" multiplier="1"/>
  </joint>
  <link name="robotiq_2f_85_right_spring_link">
    <inertial>
      <mass value="0.1"/>
      <origin rpy="-0.7068 0 0" xyz="0 0.018 0.018"/>
      <inertia ixx="0.0385416666667" ixy="0" ixz="0" iyy="0.0485416666667" iyz="0" izz="0.0166666666667"/>
    </inertial>
    <visual>
      <geometry>
        <mesh filename="package://robotiq_2f_85_gripper_visualization/meshes/visual/spring_link.dae" scale="0.001 0.001 0.001"/>
      </geometry>
    </visual>
    <collision>
      <origin rpy="-0.7068 0 0" xyz="0 0.025 0.015"/>
      <geometry>
        <box size="0.004 0.002 0.0065"/>
      </geometry>
    </collision>
  </link>
  <!-- left finger -->
  <joint name="robotiq_2f_85_left_driver_joint" type="revolute">
    <origin rpy="0 0 3.141592653589793" xyz="0 -0.0306011 0.054904"/>
    <parent link="robotiq_2f_85_base"/>
    <child link="robotiq_2f_85_left_driver"/>
    <axis xyz="1 0 0"/>
    <limit effort="176" lower="0.0" upper="0.872664444444" velocity="1.91986177778"/>
    <mimic joint="robotiq_2f_85_right_driver_joint" multiplier="1"/>
  </joint>
  <link name="robotiq_2f_85_left_driver">
    <inertial>
      <mass value="0.1"/>
      <origin rpy="0 0 0" xyz="0 0.02 0"/>
      <inertia ixx="0.0166666666667" ixy="0" ixz="0" iyy="0.00666666666667" iyz="0" izz="0.0166666666667"/>
    </inertial>
    <visual>
      <geometry>
        <mesh filename="package://robotiq_2f_85_gripper_visualization/meshes/visual/driver.dae" scale="0.001 0.001 0.001"/>
      </geometry>
    </visual>
    <collision>
      <origin rpy="-0.1 0 0" xyz="0 0.01 0"/>
      <geometry>
        <box size="0.002 0.004 0.002"/>
      </geometry>
    </collision>
  </link>
  <joint name="robotiq_2f_85_left_coupler_joint" type="fixed">
    <origin rpy="0 0 0" xyz="0 0.0315 -0.0041"/>
    <parent link="robotiq_2f_85_left_driver"/>
    <child link="robotiq_2f_85_left_coupler"/>
  </joint>
  <link name="robotiq_2f_85_left_coupler">
    <inertial>
      <mass value="0.1"/>
      <origin rpy="-1.7 0 0" xyz="0 0.0 0.025"/>
      <inertia ixx="0.0385416666667" ixy="0" ixz="0" iyy="0.0108333333333" iyz="0" izz="0.0427083333333"/>
    </inertial>
    <visual>
      <geometry>
        <mesh filename="package://robotiq_2f_85_gripper_visualization/meshes/visual/coupler.dae" scale="0.001 0.001 0.001"/>
      </geometry>
    </visual>
    <collision>
      <origin rpy="-1.7 0 0" xyz="0 0.0 0.025"/>
      <geometry>
        <box size="0.03 0.065 0.02"/>
      </geometry>
    </collision>
  </link>
  <joint name="robotiq_2f_85_left_follower_joint" type="revolute">
    <origin rpy="0 0 0" xyz="0 0.0061 0.0471"/>
    <parent link="robotiq_2f_85_left_coupler"/>
    <child link="robotiq_2f_85_left_follower"/>
    <axis xyz="1 0 0"/>
    <limit effort="176" lower="-2.96705911111" upper="2.96705911111" velocity="1.91986177778"/>
    <mimic joint="robotiq_2f_85_right_driver_joint" multiplier="-1"/>
  </joint>
  <link name="robotiq_2f_85_left_follower">
    <inertial>
      <mass value="0.1"/>
      <origin xyz="0 -0.018 0.022"/>
      <inertia ixx="0.021075" ixy="0" ixz="0" iyy="0.0225333333333" iyz="0" izz="0.00520833333333"/>
    </inertial>
    <visual>
      <geometry>
        <mesh filename="package://robotiq_2f_85_gripper_visualization/meshes/visual/follower.dae" scale="0.001 0.001 0.001"/>
      </geometry>
    </visual>
    <collision>
      <origin rpy="0 0 0" xyz="0 -0.01 0.022"/>
      <geometry>
        <box size="0.002 0.0015 0.0048"/>
      </geometry>
    </collision>
  </link>
  <joint name="robotiq_2f_85_left_pad_joint" type="revolute">
    <parent link="robotiq_2f_85_left_follower"/>
    <child link="robotiq_2f_85_left_pad"/>
    <axis xyz="0 0 1"/>
    <limit effort="200" lower="0" upper="0" velocity="0"/>
    <mimic joint="robotiq_2f_85_right_driver_joint" multiplier="0"/>
  </joint>
  <link name="robotiq_2f_85_left_pad">
    <inertial>
      <mass value="0.1"/>
      <origin xyz="0 -0.022 0.031"/>
      <inertia ixx="0.0113333333333" ixy="0" ixz="0" iyy="0.0141333333333" iyz="0" izz="0.00386666666667"/>
    </inertial>
    <visual>
      <geometry>
        <mesh filename="package://robotiq_2f_85_gripper_visualization/meshes/visual/pad.dae" scale="0.001 0.001 0.001"/>
      </geometry>
    </visual>
    <collision>
      <origin rpy="0 0 0" xyz="0 -0.022 0.031"/>
      <geometry>
        <box size="0.02 0.008 0.036"/>
      </geometry>
    </collision>
  </link>
  <joint name="robotiq_2f_85_left_spring_link_joint" type="revolute">
    <origin rpy="0 0 3.141592653589793" xyz="0 -0.012 0.0614"/>
    <parent link="robotiq_2f_85_base"/>
    <child link="robotiq_2f_85_left_spring_link"/>
    <axis xyz="1 0 0"/>
    <limit effort="176" lower="-2.96705911111" upper="2.96705911111" velocity="1.91986177778"/>
    <mimic joint="robotiq_2f_85_right_driver_joint" multiplier="1"/>
  </joint>
  <link name="robotiq_2f_85_left_spring_link">
    <inertial>
      <mass value="0.1"/>
      <origin rpy="-0.7068 0 0" xyz="0 0.018 0.018"/>
      <inertia ixx="0.0385416666667" ixy="0" ixz="0" iyy="0.0485416666667" iyz="0" izz="0.0166666666667"/>
    </inertial>
    <visual>
      <geometry>
        <mesh filename="package://robotiq_2f_85_gripper_visualization/meshes/visual/spring_link.dae" scale="0.001 0.001 0.001"/>
      </geometry>
    </visual>
    <collision>
      <origin rpy="-0.7068 0 0" xyz="0 0.025 0.015"/>
      <geometry>
        <box size="0.004 0.002 0.0065"/>
      </geometry>
    </collision>
  </link>
  <gazebo reference="robotiq_2f_85_right_pad">
    <kp>1000000.0</kp>
    <kd>1.0</kd>
    <mu1>100.0</mu1>
    <mu2>100.0</mu2>
    <minDepth>0.003</minDepth>
  </gazebo>
  <gazebo reference="robotiq_2f_85_left_pad">
    <kp>1000000.0</kp>
    <kd>1.0</kd>
    <mu1>100.0</mu1>
    <mu2>100.0</mu2>
    <minDepth>0.003</minDepth>
  </gazebo>
  <gazebo>
    <gripper name="grasping">
      <grasp_check>
        <attach_steps>1</attach_steps>
        <detach_steps>1</detach_steps>
        <min_contact_count>1</min_contact_count>
      </grasp_check>
      <gripper_link>robotiq_2f_85_left_pad</gripper_link>
      <palm_link>robotiq_2f_85_right_pad</palm_link>
    </gripper>
  </gazebo>
  <gazebo reference="robotiq_2f_85_right_driver_joint">
    <implicitSpringDamper>1</implicitSpringDamper>
  </gazebo>
  <gazebo reference="robotiq_2f_85_right_coupler_joint">
    <implicitSpringDamper>1</implicitSpringDamper>
  </gazebo>
  <gazebo reference="robotiq_2f_85_right_follower_joint">
    <implicitSpringDamper>1</implicitSpringDamper>
  </gazebo>
  <gazebo reference="robotiq_2f_85_right_pad_joint">
    <implicitSpringDamper>1</implicitSpringDamper>
  </gazebo>
  <gazebo reference="robotiq_2f_85_right_spring_link_joint">
    <implicitSpringDamper>1</implicitSpringDamper>
  </gazebo>
  <gazebo reference="robotiq_2f_85_left_driver_joint">
    <implicitSpringDamper>1</implicitSpringDamper>
  </gazebo>
  <gazebo reference="robotiq_2f_85_left_coupler_joint">
    <implicitSpringDamper>1</implicitSpringDamper>
  </gazebo>
  <gazebo reference="robotiq_2f_85_left_follower_joint">
    <implicitSpringDamper>1</implicitSpringDamper>
  </gazebo>
  <gazebo reference="robotiq_2f_85_left_pad_joint">
    <implicitSpringDamper>1</implicitSpringDamper>
  </gazebo>
  <gazebo reference="robotiq_2f_85_left_spring_link_joint">
    <implicitSpringDamper>1</implicitSpringDamper>
  </gazebo>
  <transmission name="robotiq_2f_85_right_driver_trans">
    <type>transmission_interface/SimpleTransmission</type>
    <joint name="robotiq_2f_85_right_driver_joint">
      <hardwareInterface>hardware_interface/PositionJointInterface</hardwareInterface>
    </joint>
    <actuator name="robotiq_2f_85_right_driver_motor">
      <hardwareInterface>hardware_interface/PositionJointInterface</hardwareInterface>
      <mechanicalReduction>1</mechanicalReduction>
    </actuator>
  </transmission>
  <gazebo>
    <plugin filename="libroboticsgroup_gazebo_mimic_joint_plugin.so" name="robotiq_2f_85_right_follower_joint_plugin">
      <joint>robotiq_2f_85_right_driver_joint</joint>
      <mimicJoint>robotiq_2f_85_right_follower_joint</mimicJoint>
      <multiplier>-1</multiplier>
    </plugin>
    <plugin filename="libroboticsgroup_gazebo_mimic_joint_plugin.so" name="robotiq_2f_85_right_spring_link_joint_plugin">
      <joint>robotiq_2f_85_right_driver_joint</joint>
      <mimicJoint>robotiq_2f_85_right_spring_link_joint</mimicJoint>
      <multiplier>1</multiplier>
    </plugin>
    <plugin filename="libroboticsgroup_gazebo_mimic_joint_plugin.so" name="robotiq_2f_85_left_follower_joint_plugin">
      <joint>robotiq_2f_85_right_driver_joint</joint>
      <mimicJoint>robotiq_2f_85_left_follower_joint</mimicJoint>
      <multiplier>-1</multiplier>
    </plugin>
    <plugin filename="libroboticsgroup_gazebo_mimic_joint_plugin.so" name="robotiq_2f_85_left_spring_link_joint_plugin">
      <joint>robotiq_2f_85_right_driver_joint</joint>
      <mimicJoint>robotiq_2f_85_left_spring_link_joint</mimicJoint>
      <multiplier>1</multiplier>
    </plugin>
    <plugin filename="libroboticsgroup_gazebo_mimic_joint_plugin.so" name="robotiq_2f_85_left_driver_joint_plugin">
      <joint>robotiq_2f_85_right_driver_joint</joint>
      <mimicJoint>robotiq_2f_85_left_driver_joint</mimicJoint>
      <multiplier>1</multiplier>
    </plugin>
    <plugin filename="libroboticsgroup_gazebo_mimic_joint_plugin.so" name="robotiq_2f_85_right_pad_joint_plugin">
      <joint>robotiq_2f_85_right_pad_joint</joint>
      <mimicJoint>robotiq_2f_85_right_follower_joint</mimicJoint>
      <multiplier>0</multiplier>
    </plugin>
    <plugin filename="libroboticsgroup_gazebo_mimic_joint_plugin.so" name="robotiq_2f_85_left_pad_joint_plugin">
      <joint>robotiq_2f_85_left_pad_joint</joint>
      <mimicJoint>robotiq_2f_85_right_follower_joint</mimicJoint>
      <multiplier>0</multiplier>
    </plugin>
  </gazebo>
</robot>
