<?xml version="1.0" encoding="utf-8"?>
<!-- =================================================================================== -->
<!-- |    This document was autogenerated by xacro from src/ur_e_description/urdf/ur5e_joint_limited_robot.urdf.xacro | -->
<!-- |    EDITING THIS FILE BY HAND IS NOT RECOMMENDED                                 | -->
<!-- =================================================================================== -->
<robot name="ur5e">
  <gazebo>
    <plugin filename="libgazebo_ros_control.so" name="ros_control">
      <robotNamespace>/</robotNamespace>
      <!--robotNamespace>/</robotNamespace-->
      <robotSimType>gazebo_ros_control/DefaultRobotHWSim</robotSimType>
    </plugin>
    <!--
    <plugin name="gazebo_ros_power_monitor_controller" filename="libgazebo_ros_power_monitor.so">
      <alwaysOn>true</alwaysOn>
      <updateRate>1.0</updateRate>
      <timeout>5</timeout>
      <powerStateTopic>power_state</powerStateTopic>
      <powerStateRate>10.0</powerStateRate>
      <fullChargeCapacity>87.78</fullChargeCapacity>     
      <dischargeRate>-474</dischargeRate>
      <chargeRate>525</chargeRate>
      <dischargeVoltage>15.52</dischargeVoltage>
      <chargeVoltage>16.41</chargeVoltage>
    </plugin>
-->
  </gazebo>
  <!--property name="shoulder_height" value="0.089159" /-->
  <!--property name="shoulder_offset" value="0.13585" /-->
  <!-- shoulder_offset - elbow_offset + wrist_1_length = 0.10915 -->
  <!--property name="upper_arm_length" value="0.42500" /-->
  <!--property name="elbow_offset" value="0.1197" /-->
  <!-- CAD measured -->
  <!--property name="forearm_length" value="0.39225" /-->
  <!--property name="wrist_1_length" value="0.093" /-->
  <!-- CAD measured -->
  <!--property name="wrist_2_length" value="0.09465" /-->
  <!-- In CAD this distance is 0.930, but in the spec it is 0.09465 -->
  <!--property name="wrist_3_length" value="0.0823" /-->
  <!-- manually measured -->
  <link name="base_link">
    <visual>
      <geometry>
        <mesh filename="package://ur_e_description/meshes/ur5e/visual/base.dae"/>
      </geometry>
      <material name="LightGrey">
        <color rgba="0.7 0.7 0.7 1.0"/>
      </material>
    </visual>
    <collision>
      <geometry>
        <mesh filename="package://ur_e_description/meshes/ur5e/collision/base.stl"/>
      </geometry>
    </collision>
    <inertial>
      <mass value="4.0"/>
      <origin rpy="0 0 0" xyz="0.0 0.0 0.0"/>
      <inertia ixx="0.00443333156" ixy="0.0" ixz="0.0" iyy="0.00443333156" iyz="0.0" izz="0.0072"/>
    </inertial>
  </link>
  <joint name="shoulder_pan_joint" type="revolute">
    <parent link="base_link"/>
    <child link="shoulder_link"/>
    <origin rpy="0.0 0.0 0.0" xyz="0.0 0.0 0.163"/>
    <axis xyz="0 0 1"/>
    <limit effort="150.0" lower="-3.14159265359" upper="3.14159265359" velocity="3.14"/>
    <dynamics damping="0.0" friction="0.0"/>
  </joint>
  <link name="shoulder_link">
    <visual>
      <geometry>
        <mesh filename="package://ur_e_description/meshes/ur5e/visual/shoulder.dae"/>
      </geometry>
      <material name="LightGrey">
        <color rgba="0.7 0.7 0.7 1.0"/>
      </material>
    </visual>
    <collision>
      <geometry>
        <mesh filename="package://ur_e_description/meshes/ur5e/collision/shoulder.stl"/>
      </geometry>
    </collision>
    <inertial>
      <mass value="3.7"/>
      <origin rpy="0 0 0" xyz="0.0 0.0 0.0"/>
      <inertia ixx="0.010267495893" ixy="0.0" ixz="0.0" iyy="0.010267495893" iyz="0.0" izz="0.00666"/>
    </inertial>
  </link>
  <joint name="shoulder_lift_joint" type="revolute">
    <parent link="shoulder_link"/>
    <child link="upper_arm_link"/>
    <origin rpy="0.0 1.57079632679 0.0" xyz="0.0 0.138 0.0"/>
    <axis xyz="0 1 0"/>
    <limit effort="150.0" lower="-3.14159265359" upper="3.14159265359" velocity="3.14"/>
    <dynamics damping="0.0" friction="0.0"/>
  </joint>
  <link name="upper_arm_link">
    <visual>
      <geometry>
        <mesh filename="package://ur_e_description/meshes/ur5e/visual/upperarm.dae"/>
      </geometry>
      <material name="LightGrey">
        <color rgba="0.7 0.7 0.7 1.0"/>
      </material>
    </visual>
    <collision>
      <geometry>
        <mesh filename="package://ur_e_description/meshes/ur5e/collision/upperarm.stl"/>
      </geometry>
    </collision>
    <inertial>
      <mass value="8.393"/>
      <origin rpy="0 0 0" xyz="0.0 0.0 0.2125"/>
      <inertia ixx="0.133885781862" ixy="0.0" ixz="0.0" iyy="0.133885781862" iyz="0.0" izz="0.0151074"/>
    </inertial>
  </link>
  <joint name="elbow_joint" type="revolute">
    <parent link="upper_arm_link"/>
    <child link="forearm_link"/>
    <origin rpy="0.0 0.0 0.0" xyz="0.0 -0.131 0.425"/>
    <axis xyz="0 1 0"/>
    <limit effort="150.0" lower="-3.14159265359" upper="3.14159265359" velocity="3.14"/>
    <dynamics damping="0.0" friction="0.0"/>
  </joint>
  <link name="forearm_link">
    <visual>
      <geometry>
        <mesh filename="package://ur_e_description/meshes/ur5e/visual/forearm.dae"/>
      </geometry>
      <material name="LightGrey">
        <color rgba="0.7 0.7 0.7 1.0"/>
      </material>
    </visual>
    <collision>
      <geometry>
        <mesh filename="package://ur_e_description/meshes/ur5e/collision/forearm.stl"/>
      </geometry>
    </collision>
    <inertial>
      <mass value="2.275"/>
      <origin rpy="0 0 0" xyz="0.0 0.0 0.196"/>
      <inertia ixx="0.0311796208615" ixy="0.0" ixz="0.0" iyy="0.0311796208615" iyz="0.0" izz="0.004095"/>
    </inertial>
  </link>
  <joint name="wrist_1_joint" type="revolute">
    <parent link="forearm_link"/>
    <child link="wrist_1_link"/>
    <origin rpy="0.0 1.57079632679 0.0" xyz="0.0 0.0 0.392"/>
    <axis xyz="0 1 0"/>
    <limit effort="28.0" lower="-3.14159265359" upper="3.14159265359" velocity="6.28"/>
    <dynamics damping="0.0" friction="0.0"/>
  </joint>
  <link name="wrist_1_link">
    <visual>
      <geometry>
        <mesh filename="package://ur_e_description/meshes/ur5e/visual/wrist1.dae"/>
      </geometry>
      <material name="LightGrey">
        <color rgba="0.7 0.7 0.7 1.0"/>
      </material>
    </visual>
    <collision>
      <geometry>
        <mesh filename="package://ur_e_description/meshes/ur5e/collision/wrist1.stl"/>
      </geometry>
    </collision>
    <inertial>
      <mass value="1.219"/>
      <origin rpy="0 0 0" xyz="0.0 0.127 0.0"/>
      <inertia ixx="0.00255989897604" ixy="0.0" ixz="0.0" iyy="0.00255989897604" iyz="0.0" izz="0.0021942"/>
    </inertial>
  </link>
  <joint name="wrist_2_joint" type="revolute">
    <parent link="wrist_1_link"/>
    <child link="wrist_2_link"/>
    <origin rpy="0.0 0.0 0.0" xyz="0.0 0.127 0.0"/>
    <axis xyz="0 0 1"/>
    <limit effort="28.0" lower="-3.14159265359" upper="3.14159265359" velocity="6.28"/>
    <dynamics damping="0.0" friction="0.0"/>
  </joint>
  <link name="wrist_2_link">
    <visual>
      <geometry>
        <mesh filename="package://ur_e_description/meshes/ur5e/visual/wrist2.dae"/>
      </geometry>
      <material name="LightGrey">
        <color rgba="0.7 0.7 0.7 1.0"/>
      </material>
    </visual>
    <collision>
      <geometry>
        <mesh filename="package://ur_e_description/meshes/ur5e/collision/wrist2.stl"/>
      </geometry>
    </collision>
    <inertial>
      <mass value="1.219"/>
      <origin rpy="0 0 0" xyz="0.0 0.0 0.1"/>
      <inertia ixx="0.00255989897604" ixy="0.0" ixz="0.0" iyy="0.00255989897604" iyz="0.0" izz="0.0021942"/>
    </inertial>
  </link>
  <joint name="wrist_3_joint" type="revolute">
    <parent link="wrist_2_link"/>
    <child link="wrist_3_link"/>
    <origin rpy="0.0 0.0 0.0" xyz="0.0 0.0 0.1"/>
    <axis xyz="0 1 0"/>
    <limit effort="28.0" lower="-3.14159265359" upper="3.14159265359" velocity="6.28"/>
    <dynamics damping="0.0" friction="0.0"/>
  </joint>
  <link name="wrist_3_link">
    <visual>
      <geometry>
        <mesh filename="package://ur_e_description/meshes/ur5e/visual/wrist3.dae"/>
      </geometry>
      <material name="LightGrey">
        <color rgba="0.7 0.7 0.7 1.0"/>
      </material>
    </visual>
    <collision>
      <geometry>
        <mesh filename="package://ur_e_description/meshes/ur5e/collision/wrist3.stl"/>
      </geometry>
    </collision>
    <inertial>
      <mass value="0.1879"/>
      <origin rpy="1.57079632679 0 0" xyz="0.0 0.0771 0.0"/>
      <inertia ixx="9.89041005217e-05" ixy="0.0" ixz="0.0" iyy="9.89041005217e-05" iyz="0.0" izz="0.0001321171875"/>
    </inertial>
  </link>
  <joint name="ee_fixed_joint" type="fixed">
    <parent link="wrist_3_link"/>
    <child link="ee_link"/>
    <origin rpy="0.0 0.0 1.57079632679" xyz="0.0 0.1 0.0"/>
  </joint>
  <link name="ee_link">
    <collision>
      <geometry>
        <box size="0.01 0.01 0.01"/>
      </geometry>
      <origin rpy="0 0 0" xyz="-0.01 0 0"/>
    </collision>
  </link>
  <material name="realSense_aluminum">
    <color rgba="0.5 0.5 0.5 1"/>
  </material>
  <!-- camera body, with origin at bottom screw mount -->
  <joint name="realSense_joint" type="fixed">
    <origin rpy="-3.1296068 0.028976 1.6645942" xyz="0.011013 0.094580 -0.10724"/>
    <parent link="wrist_3_link"/>
    <child link="realSense_bottom_screw_frame"/>
  </joint>
  <link name="realSense_bottom_screw_frame"/>
  <joint name="realSense_link_joint" type="fixed">
    <origin rpy="0 0 0" xyz="0 0.0175 0.0125"/>
    <parent link="realSense_bottom_screw_frame"/>
    <child link="realSense_link"/>
  </joint>
  <link name="realSense_link">
    <visual>
      <origin rpy="1.57079632679 0 1.57079632679" xyz="0.0149 -0.0175 0"/>
      <geometry>
        <!-- <box size="${d435_cam_width} ${d435_cam_height} ${d435_cam_depth}"/> -->
        <!-- <mesh filename="package://ur_e_description/meshes/ur5e/visual/base.dae" /> -->
        <mesh filename="package://realsense2_description/meshes/d435.dae"/>
      </geometry>
      <material name="realSense_aluminum"/>
    </visual>
    <collision>
      <origin rpy="0 0 0" xyz="0 -0.0175 0"/>
      <geometry>
        <box size="0.02505 0.09 0.025"/>
      </geometry>
    </collision>
    <inertial>
      <!-- The following are not reliable values, and should not be used for modeling -->
      <mass value="0.564"/>
      <origin xyz="0 0 0"/>
      <inertia ixx="0.003881243" ixy="0.0" ixz="0.0" iyy="0.000498940" iyz="0.0" izz="0.003879257"/>
    </inertial>
  </link>
  <!-- camera depth joints and links -->
  <joint name="realSense_depth_joint" type="fixed">
    <origin rpy="0 0 0" xyz="0 0 0"/>
    <parent link="realSense_link"/>
    <child link="realSense_depth_frame"/>
  </joint>
  <link name="realSense_depth_frame"/>
  <joint name="realSense_depth_optical_joint" type="fixed">
    <origin rpy="-1.57079632679 0 -1.57079632679" xyz="0 0 0"/>
    <parent link="realSense_depth_frame"/>
    <child link="realSense_depth_optical_frame"/>
  </joint>
  <link name="realSense_depth_optical_frame"/>
  <!-- camera left IR joints and links -->
  <joint name="realSense_left_ir_joint" type="fixed">
    <origin rpy="0 0 0" xyz="0 0.0 0"/>
    <parent link="realSense_depth_frame"/>
    <child link="realSense_left_ir_frame"/>
  </joint>
  <link name="realSense_left_ir_frame"/>
  <joint name="realSense_left_ir_optical_joint" type="fixed">
    <origin rpy="-1.57079632679 0 -1.57079632679" xyz="0 0 0"/>
    <parent link="realSense_left_ir_frame"/>
    <child link="realSense_left_ir_optical_frame"/>
  </joint>
  <link name="realSense_left_ir_optical_frame"/>
  <!-- camera right IR joints and links -->
  <joint name="realSense_right_ir_joint" type="fixed">
    <origin rpy="0 0 0" xyz="0 0.0 0"/>
    <parent link="realSense_depth_frame"/>
    <child link="realSense_right_ir_frame"/>
  </joint>
  <link name="realSense_right_ir_frame"/>
  <joint name="realSense_right_ir_optical_joint" type="fixed">
    <origin rpy="-1.57079632679 0 -1.57079632679" xyz="0 0 0"/>
    <parent link="realSense_right_ir_frame"/>
    <child link="realSense_right_ir_optical_frame"/>
  </joint>
  <link name="realSense_right_ir_optical_frame"/>
  <!-- camera color joints and links -->
  <joint name="realSense_color_joint" type="fixed">
    <origin rpy="0 0 0" xyz="0 0.0 0"/>
    <parent link="realSense_depth_frame"/>
    <child link="realSense_color_frame"/>
  </joint>
  <link name="realSense_color_frame"/>
  <joint name="realSense_color_optical_joint" type="fixed">
    <origin rpy="-1.57079632679 0 -1.57079632679" xyz="0 0 0"/>
    <parent link="realSense_color_frame"/>
    <child link="realsense_camera_link"/>
  </joint>
  <link name="realsense_camera_link"/>
  <gazebo reference="realSense_link">
    <self_collide>0</self_collide>
    <enable_wind>0</enable_wind>
    <kinematic>0</kinematic>
    <gravity>1</gravity>
    <!--<mu>1</mu>-->
    <mu2>1</mu2>
    <fdir1>0 0 0</fdir1>
    <!--<slip1>0</slip1>
      <slip2>0</slip2>-->
    <kp>1e+13</kp>
    <kd>1</kd>
    <!--<max_vel>0.01</max_vel>
      <min_depth>0</min_depth>-->
    <sensor name="realSensecolor" type="camera">
      <camera name="realSense">
        <horizontal_fov>0.7508</horizontal_fov>
        <image>
          <width>640</width>
          <height>480</height>
          <format>RGB_INT8</format>
        </image>
        <clip>
          <near>0.1</near>
          <far>100</far>
        </clip>
        <noise>
          <type>gaussian</type>
          <mean>0.0</mean>
          <stddev>0.007</stddev>
        </noise>
      </camera>
      <always_on>1</always_on>
      <update_rate>30</update_rate>
      <visualize>0</visualize>
    </sensor>
    <sensor name="realSenseired1" type="camera">
      <camera name="realSense">
        <horizontal_fov>0.7508</horizontal_fov>
        <image>
          <width>640</width>
          <height>480</height>
          <format>L_INT8</format>
        </image>
        <clip>
          <near>0.1</near>
          <far>100</far>
        </clip>
        <noise>
          <type>gaussian</type>
          <mean>0.0</mean>
          <stddev>0.05</stddev>
        </noise>
      </camera>
      <always_on>1</always_on>
      <update_rate>30</update_rate>
      <visualize>0</visualize>
    </sensor>
    <sensor name="realSenseired2" type="camera">
      <camera name="realSense">
        <horizontal_fov>0.7508</horizontal_fov>
        <image>
          <width>640</width>
          <height>480</height>
          <format>L_INT8</format>
        </image>
        <clip>
          <near>0.1</near>
          <far>100</far>
        </clip>
        <noise>
          <type>gaussian</type>
          <mean>0.0</mean>
          <stddev>0.05</stddev>
        </noise>
      </camera>
      <always_on>1</always_on>
      <update_rate>30</update_rate>
      <visualize>0</visualize>
    </sensor>
    <sensor name="realSensedepth" type="depth">
      <camera name="realSense">
        <horizontal_fov>0.7508</horizontal_fov>
        <image>
          <width>640</width>
          <height>480</height>
        </image>
        <clip>
          <near>0.1</near>
          <far>100</far>
        </clip>
        <noise>
          <type>gaussian</type>
          <mean>0.0</mean>
          <stddev>0.100</stddev>
        </noise>
      </camera>
      <always_on>1</always_on>
      <update_rate>30</update_rate>
      <visualize>0</visualize>
    </sensor>
  </gazebo>
  <gazebo>
    <plugin filename="librealsense_gazebo_plugin.so" name="realsense">
      <prefix>realSense</prefix>
      <depthUpdateRate>30.0</depthUpdateRate>
      <colorUpdateRate>30.0</colorUpdateRate>
      <infraredUpdateRate>30.0</infraredUpdateRate>
      <depthTopicName>depth/image_raw</depthTopicName>
      <depthCameraInfoTopicName>depth/camera_info</depthCameraInfoTopicName>
      <colorTopicName>color/image_raw</colorTopicName>
      <colorCameraInfoTopicName>color/camera_info</colorCameraInfoTopicName>
      <!-- <infrared1TopicName>infra1/image_raw</infrared1TopicName>
      	<infrared1CameraInfoTopicName>infra1/camera_info</infrared1CameraInfoTopicName>
      	<infrared2TopicName>infra2/image_raw</infrared2TopicName>
      	<infrared2CameraInfoTopicName>infra2/camera_info</infrared2CameraInfoTopicName> -->
      <colorOpticalframeName>realsense_camera_link</colorOpticalframeName>
      <depthOpticalframeName>realsense_camera_link</depthOpticalframeName>
      <!-- <infrared1OpticalframeName>${infrared1_optical_frame}</infrared1OpticalframeName>
      	<infrared2OpticalframeName>${infrared2_optical_frame}</infrared2OpticalframeName> -->
      <rangeMinDepth>0.2</rangeMinDepth>
      <rangeMaxDepth>10.0</rangeMaxDepth>
      <pointCloud>true</pointCloud>
      <pointCloudTopicName>depth/points</pointCloudTopicName>
      <pointCloudCutoff>0.2</pointCloudCutoff>
    </plugin>
  </gazebo>
  <!-- Kinect link -->
  <material name="black">
    <color rgba="0. 0. 0. 1"/>
  </material>
  <material name="dark_grey">
    <color rgba="0.1 0.1 0.1 1"/>
  </material>
  <material name="grey">
    <color rgba="0.6 0.6 0.6 1"/>
  </material>
  <material name="white">
    <color rgba="0.9 0.9 0.9 1"/>
  </material>
  <joint name="kinect_camera_joint" type="fixed">
    <origin rpy="0.1285134 0.8828308 -1.3433447" xyz="-0.13285 0.797229 0.58769"/>
    <parent link="base_link"/>
    <child link="kinect_camera_visor"/>
  </joint>
  <link name="kinect_camera_body">
    <visual>
      <origin xyz="0. 0. 0."/>
      <geometry>
        <box size="0.0994 0.0996 0.023"/>
      </geometry>
      <material name="white"/>
    </visual>
  </link>
  <link name="kinect_camera_base">
    <visual>
      <origin xyz="-0.013 0. 0."/>
      <geometry>
        <box size="0.026 0.103 0.039"/>
      </geometry>
      <material name="grey"/>
    </visual>
  </link>
  <link name="kinect_camera_visor">
    <visual>
      <origin xyz="-0.0128 0. 0."/>
      <geometry>
        <box size="0.026 0.101 0.037"/>
      </geometry>
      <material name="black"/>
    </visual>
  </link>
  <joint name="kinect_camera_base_to_body" type="fixed">
    <parent link="kinect_camera_base"/>
    <child link="kinect_camera_body"/>
    <origin rpy="0. 0. 0." xyz="-0.0757 0. 0.008"/>
  </joint>
  <joint name="kinect_camera_base_to_visor" type="fixed">
    <parent link="kinect_camera_visor"/>
    <child link="kinect_camera_base"/>
    <origin rpy="0. 0. 0." xyz="0. 0. 0."/>
  </joint>
  <joint name="kinect_optical_joint" type="fixed">
    <origin rpy="-1.57079632679 0 -1.57079632679" xyz="0 0 0"/>
    <parent link="kinect_camera_visor"/>
    <child link="kinect_optical_frame"/>
  </joint>
  <link name="kinect_optical_frame"/>
  <transmission name="shoulder_pan_trans">
    <type>transmission_interface/SimpleTransmission</type>
    <joint name="shoulder_pan_joint">
      <hardwareInterface>hardware_interface/PositionJointInterface</hardwareInterface>
    </joint>
    <actuator name="shoulder_pan_motor">
      <mechanicalReduction>1</mechanicalReduction>
    </actuator>
  </transmission>
  <transmission name="shoulder_lift_trans">
    <type>transmission_interface/SimpleTransmission</type>
    <joint name="shoulder_lift_joint">
      <hardwareInterface>hardware_interface/PositionJointInterface</hardwareInterface>
    </joint>
    <actuator name="shoulder_lift_motor">
      <mechanicalReduction>1</mechanicalReduction>
    </actuator>
  </transmission>
  <transmission name="elbow_trans">
    <type>transmission_interface/SimpleTransmission</type>
    <joint name="elbow_joint">
      <hardwareInterface>hardware_interface/PositionJointInterface</hardwareInterface>
    </joint>
    <actuator name="elbow_motor">
      <mechanicalReduction>1</mechanicalReduction>
    </actuator>
  </transmission>
  <transmission name="wrist_1_trans">
    <type>transmission_interface/SimpleTransmission</type>
    <joint name="wrist_1_joint">
      <hardwareInterface>hardware_interface/PositionJointInterface</hardwareInterface>
    </joint>
    <actuator name="wrist_1_motor">
      <mechanicalReduction>1</mechanicalReduction>
    </actuator>
  </transmission>
  <transmission name="wrist_2_trans">
    <type>transmission_interface/SimpleTransmission</type>
    <joint name="wrist_2_joint">
      <hardwareInterface>hardware_interface/PositionJointInterface</hardwareInterface>
    </joint>
    <actuator name="wrist_2_motor">
      <mechanicalReduction>1</mechanicalReduction>
    </actuator>
  </transmission>
  <transmission name="wrist_3_trans">
    <type>transmission_interface/SimpleTransmission</type>
    <joint name="wrist_3_joint">
      <hardwareInterface>hardware_interface/PositionJointInterface</hardwareInterface>
    </joint>
    <actuator name="wrist_3_motor">
      <mechanicalReduction>1</mechanicalReduction>
    </actuator>
  </transmission>
  <gazebo reference="shoulder_link">
    <selfCollide>true</selfCollide>
  </gazebo>
  <gazebo reference="upper_arm_link">
    <selfCollide>true</selfCollide>
  </gazebo>
  <gazebo reference="forearm_link">
    <selfCollide>true</selfCollide>
  </gazebo>
  <gazebo reference="wrist_1_link">
    <selfCollide>true</selfCollide>
  </gazebo>
  <gazebo reference="wrist_3_link">
    <selfCollide>true</selfCollide>
  </gazebo>
  <gazebo reference="wrist_2_link">
    <selfCollide>true</selfCollide>
  </gazebo>
  <gazebo reference="ee_link">
    <selfCollide>true</selfCollide>
  </gazebo>
  <gazebo reference="kinect_camera_visor">
    <self_collide>0</self_collide>
    <enable_wind>0</enable_wind>
    <kinematic>0</kinematic>
    <gravity>1</gravity>
    <!--<mu>1</mu>-->
    <mu2>1</mu2>
    <fdir1>0 0 0</fdir1>
    <!--<slip1>0</slip1>
      <slip2>0</slip2>-->
    <kp>1e+13</kp>
    <kd>1</kd>
    <!--<max_vel>0.01</max_vel>
      <min_depth>0</min_depth>-->
    <!-- <sensor name="kinectcolor" type="camera">
        <camera name="kinect">
          <horizontal_fov>${69.4*deg_to_rad}</horizontal_fov>
          <image>
            <width>1920</width>
            <height>1080</height>
            <format>RGB_INT8</format>
          </image>
          <clip>
            <near>0.1</near>
            <far>100</far>
          </clip>
          <noise>
            <type>gaussian</type>
            <mean>0.0</mean>
            <stddev>0.007</stddev>
          </noise>
        </camera>
        <always_on>1</always_on>
        <update_rate>30</update_rate>
        <visualize>0</visualize>
      </sensor>
      <sensor name="kinectired1" type="camera">
        <camera name="kinect">
          <horizontal_fov>${85.2*deg_to_rad}</horizontal_fov>
          <image>
            <width>1280</width>
            <height>720</height>
            <format>L_INT8</format>
          </image>
          <clip>
            <near>0.1</near>
            <far>100</far>
          </clip>
          <noise>
            <type>gaussian</type>
            <mean>0.0</mean>
            <stddev>0.05</stddev>
          </noise>
        </camera>
        <always_on>1</always_on>
        <update_rate>90</update_rate>
        <visualize>0</visualize>
      </sensor>
     <sensor name="kinectired2" type="camera">
        <camera name="kinect">
          <horizontal_fov>${85.2*deg_to_rad}</horizontal_fov>
          <image>
            <width>1280</width>
            <height>720</height>
            <format>L_INT8</format>
          </image>
          <clip>
            <near>0.1</near>
            <far>100</far>
          </clip>
          <noise>
            <type>gaussian</type>
            <mean>0.0</mean>
            <stddev>0.05</stddev>
          </noise>
        </camera>
        <always_on>1</always_on>
        <update_rate>90</update_rate>
        <visualize>0</visualize>
      </sensor> -->
    <sensor name="kinectdepth" type="depth">
      <camera name="kinect">
        <horizontal_fov>1.0382</horizontal_fov>
        <image>
          <width>1280</width>
          <height>720</height>
          <format>B8G8R8</format>
        </image>
        <clip>
          <near>0.1</near>
          <far>100</far>
        </clip>
        <noise>
          <type>gaussian</type>
          <mean>0.0</mean>
          <stddev>0.100</stddev>
        </noise>
      </camera>
      <always_on>1</always_on>
      <update_rate>30</update_rate>
      <visualize>0</visualize>
      <plugin filename="libgazebo_ros_openni_kinect.so" name="kinect_controller">
        <baseline>0.2</baseline>
        <alwaysOn>true</alwaysOn>
        <updateRate>30.0</updateRate>
        <cameraName>kinect_ir</cameraName>
        <imageTopicName>/kinect/color/image_raw</imageTopicName>
        <cameraInfoTopicName>/kinect/color/camera_info</cameraInfoTopicName>
        <depthImageTopicName>/kinect/depth/image_raw</depthImageTopicName>
        <depthImageInfoTopicName>/kinect/depth/camera_info</depthImageInfoTopicName>
        <pointCloudTopicName>/kinect/depth/points</pointCloudTopicName>
        <frameName>kinect_optical_frame</frameName>
        <pointCloudCutoff>0.5</pointCloudCutoff>
        <pointCloudCutoffMax>3.0</pointCloudCutoffMax>
        <distortionK1>0.00000001</distortionK1>
        <distortionK2>0.00000001</distortionK2>
        <distortionK3>0.00000001</distortionK3>
        <distortionT1>0.00000001</distortionT1>
        <distortionT2>0.00000001</distortionT2>
        <CxPrime>0</CxPrime>
        <Cx>0</Cx>
        <Cy>0</Cy>
        <focalLength>0</focalLength>
        <hackBaseline>0</hackBaseline>
      </plugin>
    </sensor>
  </gazebo>
  <!-- <gazebo>
      <plugin name="kinect" filename="librealsense_gazebo_plugin.so">
        <prefix>kinect</prefix>
      	<depthUpdateRate>60.0</depthUpdateRate>
      	<colorUpdateRate>60.0</colorUpdateRate>
      	<infraredUpdateRate>60.0</infraredUpdateRate>
      	<depthTopicName>depth/image_raw</depthTopicName>
      	<depthCameraInfoTopicName>depth/camera_info</depthCameraInfoTopicName>
      	<colorTopicName>color/image_raw</colorTopicName>
      	<colorCameraInfoTopicName>color/camera_info</colorCameraInfoTopicName> -->
  <!-- <infrared1TopicName>infra1/image_raw</infrared1TopicName>
      	<infrared1CameraInfoTopicName>infra1/camera_info</infrared1CameraInfoTopicName> -->
  <!--	<infrared2TopicName>infra2/image_raw</infrared2TopicName> 
      	<infrared2CameraInfoTopicName>infra2/camera_info</infrared2CameraInfoTopicName>-->
  <!-- <colorOpticalframeName>kinect_optical_frame</colorOpticalframeName>
      	<depthOpticalframeName>kinect_optical_frame</depthOpticalframeName> -->
  <!-- <infrared1OpticalframeName>kinect_camera_visor</infrared1OpticalframeName> -->
  <!--<infrared2OpticalframeName>${infrared2_optical_frame}</infrared2OpticalframeName>-->
  <!-- <rangeMinDepth>0.25</rangeMinDepth>
      	<rangeMaxDepth>5.88</rangeMaxDepth>
      	<pointCloud>true</pointCloud>
      	<pointCloudTopicName>depth/points</pointCloudTopicName>
      	<pointCloudCutoff>0.5</pointCloudCutoff>
      </plugin>
    </gazebo> -->
  <!-- ROS base_link to UR 'Base' Coordinates transform -->
  <link name="base"/>
  <joint name="base_link-base_fixed_joint" type="fixed">
    <!-- NOTE: this rotation is only needed as long as base_link itself is
                 not corrected wrt the real robot (ie: rotated over 180
                 degrees)
      -->
    <!-- Take the rotation back -->
    <!-- <origin rpy="0 0 -3.14159265359" xyz="0 0 0"/> -->
    <origin rpy="0 0 0" xyz="0 0 0"/>
    <parent link="base_link"/>
    <child link="base"/>
  </joint>
  <!-- Frame coincident with all-zeros TCP on UR controller -->
  <link name="tool0"/>
  <joint name="wrist_3_link-tool0_fixed_joint" type="fixed">
    <origin rpy="-1.57079632679 0 0" xyz="0 0.1 0"/>
    <parent link="wrist_3_link"/>
    <child link="tool0"/>
  </joint>
  <link name="world"/>
  <!-- Adding table to the world -->
  <link name="table">
    <origin rpy="0 0 0" xyz="0.0 0.0 0.0"/>
    <inertial>
      <mass value="5"/>
      <origin xyz="0 0 0"/>
      <inertia ixx="1" ixy="0.0" ixz="0.0" iyy="1" iyz="0.0" izz="1"/>
    </inertial>
    <visual>
      <geometry>
        <mesh filename="package://ur_e_description/meshes/table/visual/table.dae"/>
      </geometry>
    </visual>
    <collision>
      <geometry>
        <mesh filename="package://ur_e_description/meshes/table/collision/table.obj"/>
      </geometry>
    </collision>
  </link>
  <joint name="world_joint" type="fixed">
    <parent link="world"/>
    <child link="table"/>
    <origin rpy="0.0 0.0 -1.57" xyz="0.0 0.0 -0.005"/>
  </joint>
  <!-- fixing robot base link to the table -->
  <joint name="table_joint" type="fixed">
    <parent link="table"/>
    <child link="base_link"/>
    <origin rpy="0.0 0.0 0" xyz="0 -0.24 0.0"/>
  </joint>
  <joint name="robotiq_ur_coupler_coupler_joint" type="fixed">
    <!-- total height of coupler, minus the depth of robot end-effector shape and the gripper small depth-->
    <origin rpy="0 0 0" xyz="0 0 0.0075"/>
    <parent link="tool0"/>
    <child link="robotiq_ur_coupler"/>
  </joint>
  <link name="robotiq_ur_coupler">
    <visual>
      <origin rpy="0 0 0" xyz="0 0 -0.005465"/>
      <geometry>
        <!-- only the visible part of the coupler -->
        <cylinder length="0.0139" radius="0.0375"/>
      </geometry>
      <material name="dark_grey">
        <color rgba="0.05 0.05 0.05 1"/>
      </material>
    </visual>
    <collision>
      <origin rpy="0 0 0" xyz="0 0 0"/>
      <geometry>
        <cylinder length="0.0135" radius="0.0375"/>
      </geometry>
    </collision>
    <inertial>
      <mass value="0.3"/>
      <origin xyz="0 0 0.00695"/>
      <inertia ixx="0.110299" ixy="0" ixz="0" iyy="0.110299" iyz="0" izz="0.2109375"/>
    </inertial>
  </link>
  <!-- the ee link of gripper -->
  <joint name="robotiq_ur_coupler_robotiq_2f_85_ee_joint" type="fixed">
    <origin rpy="0 0 0" xyz="0 0 0.1493"/>
    <parent link="robotiq_2f_85_base"/>
    <child link="robotiq_2f_85_ee_link"/>
  </joint>
  <link name="robotiq_2f_85_ee_link"/>
  <!-- base -->
  <joint name="robotiq_ur_coupler_robotiq_2f_85_base_joint" type="fixed">
    <origin rpy="0 0 1.57079632679" xyz="0 0 0"/>
    <parent link="robotiq_ur_coupler"/>
    <child link="robotiq_2f_85_base"/>
  </joint>
  <link name="robotiq_2f_85_base">
    <inertial>
      <mass value="0.5"/>
      <origin xyz="0 0 0.0075"/>
      <inertia ixx="0.284375" ixy="0" ixz="0" iyy="0.284375" iyz="0" izz="0.4"/>
    </inertial>
    <visual>
      <origin rpy="0 -1.5708 0" xyz="0 0 0"/>
      <geometry>
        <mesh filename="package://robotiq_2f_85_gripper_visualization/meshes/visual/base.dae"/>
      </geometry>
    </visual>
    <collision>
      <origin rpy="0 0 0" xyz="0 0 0.015"/>
      <geometry>
        <cylinder length="0.045" radius="0.04"/>
      </geometry>
    </collision>
    <collision>
      <origin rpy="0 0 0" xyz="0 0 0.06"/>
      <geometry>
        <box size="0.03 0.03 0.06"/>
      </geometry>
    </collision>
  </link>
  <!-- right finger -->
  <joint name="robotiq_2f_85_right_driver_joint" type="revolute">
    <origin rpy="0 0 0" xyz="0 0.0306011 0.054904"/>
    <parent link="robotiq_2f_85_base"/>
    <child link="robotiq_2f_85_right_driver"/>
    <axis xyz="1 0 0"/>
    <limit effort="60" lower="0.0" upper="0.872664444444" velocity="1.91986177778"/>
  </joint>
  <link name="robotiq_2f_85_right_driver">
    <inertial>
      <mass value="0.1"/>
      <origin rpy="0 0 0" xyz="0 0.02 0"/>
      <inertia ixx="0.0166666666667" ixy="0" ixz="0" iyy="0.00666666666667" iyz="0" izz="0.0166666666667"/>
    </inertial>
    <visual>
      <geometry>
        <mesh filename="package://robotiq_2f_85_gripper_visualization/meshes/visual/driver.dae" scale="0.001 0.001 0.001"/>
      </geometry>
    </visual>
    <collision>
      <origin rpy="-0.1 0 0" xyz="0 0.01 0"/>
      <geometry>
        <box size="0.002 0.004 0.002"/>
      </geometry>
    </collision>
  </link>
  <joint name="robotiq_2f_85_right_coupler_joint" type="fixed">
    <origin rpy="0 0 0" xyz="0 0.0315 -0.0041"/>
    <parent link="robotiq_2f_85_right_driver"/>
    <child link="robotiq_2f_85_right_coupler"/>
  </joint>
  <link name="robotiq_2f_85_right_coupler">
    <inertial>
      <mass value="0.1"/>
      <origin rpy="-1.7 0 0" xyz="0 0.0 0.025"/>
      <inertia ixx="0.0385416666667" ixy="0" ixz="0" iyy="0.0108333333333" iyz="0" izz="0.0427083333333"/>
    </inertial>
    <visual>
      <geometry>
        <mesh filename="package://robotiq_2f_85_gripper_visualization/meshes/visual/coupler.dae" scale="0.001 0.001 0.001"/>
      </geometry>
    </visual>
    <collision>
      <origin rpy="-1.7 0 0" xyz="0 0.0 0.025"/>
      <geometry>
        <box size="0.03 0.065 0.02"/>
      </geometry>
    </collision>
  </link>
  <joint name="robotiq_2f_85_right_follower_joint" type="revolute">
    <origin rpy="0 0 0" xyz="0 0.0061 0.0471"/>
    <parent link="robotiq_2f_85_right_coupler"/>
    <child link="robotiq_2f_85_right_follower"/>
    <axis xyz="1 0 0"/>
    <limit effort="176" lower="-2.96705911111" upper="2.96705911111" velocity="1.91986177778"/>
    <mimic joint="robotiq_2f_85_right_driver_joint" multiplier="-1"/>
  </joint>
  <link name="robotiq_2f_85_right_follower">
    <inertial>
      <mass value="0.1"/>
      <origin xyz="0 -0.018 0.022"/>
      <inertia ixx="0.021075" ixy="0" ixz="0" iyy="0.0225333333333" iyz="0" izz="0.00520833333333"/>
    </inertial>
    <visual>
      <geometry>
        <mesh filename="package://robotiq_2f_85_gripper_visualization/meshes/visual/follower.dae" scale="0.001 0.001 0.001"/>
      </geometry>
    </visual>
    <collision>
      <origin rpy="0 0 0" xyz="0 -0.01 0.022"/>
      <geometry>
        <box size="0.002 0.0015 0.0048"/>
      </geometry>
    </collision>
  </link>
  <joint name="robotiq_2f_85_right_pad_joint" type="revolute">
    <parent link="robotiq_2f_85_right_follower"/>
    <child link="robotiq_2f_85_right_pad"/>
    <axis xyz="0 0 1"/>
    <limit effort="200" lower="0" upper="0" velocity="0"/>
    <mimic joint="robotiq_2f_85_right_driver_joint" multiplier="0"/>
  </joint>
  <link name="robotiq_2f_85_right_pad">
    <inertial>
      <mass value="0.1"/>
      <origin xyz="0 -0.022 0.031"/>
      <inertia ixx="0.0113333333333" ixy="0" ixz="0" iyy="0.0141333333333" iyz="0" izz="0.00386666666667"/>
    </inertial>
    <visual>
      <geometry>
        <mesh filename="package://robotiq_2f_85_gripper_visualization/meshes/visual/pad.dae" scale="0.001 0.001 0.001"/>
      </geometry>
    </visual>
    <collision>
      <origin rpy="0 0 0" xyz="0 -0.022 0.031"/>
      <geometry>
        <box size="0.02 0.008 0.036"/>
      </geometry>
    </collision>
  </link>
  <joint name="robotiq_2f_85_right_spring_link_joint" type="revolute">
    <origin rpy="0 0 0" xyz="0 0.012 0.0614"/>
    <parent link="robotiq_2f_85_base"/>
    <child link="robotiq_2f_85_right_spring_link"/>
    <axis xyz="1 0 0"/>
    <limit effort="176" lower="-2.96705911111" upper="2.96705911111" velocity="1.91986177778"/>
    <mimic joint="robotiq_2f_85_right_driver_joint" multiplier="1"/>
  </joint>
  <link name="robotiq_2f_85_right_spring_link">
    <inertial>
      <mass value="0.1"/>
      <origin rpy="-0.7068 0 0" xyz="0 0.018 0.018"/>
      <inertia ixx="0.0385416666667" ixy="0" ixz="0" iyy="0.0485416666667" iyz="0" izz="0.0166666666667"/>
    </inertial>
    <visual>
      <geometry>
        <mesh filename="package://robotiq_2f_85_gripper_visualization/meshes/visual/spring_link.dae" scale="0.001 0.001 0.001"/>
      </geometry>
    </visual>
    <collision>
      <origin rpy="-0.7068 0 0" xyz="0 0.025 0.015"/>
      <geometry>
        <box size="0.004 0.002 0.0065"/>
      </geometry>
    </collision>
  </link>
  <!-- left finger -->
  <joint name="robotiq_2f_85_left_driver_joint" type="revolute">
    <origin rpy="0 0 3.141592653589793" xyz="0 -0.0306011 0.054904"/>
    <parent link="robotiq_2f_85_base"/>
    <child link="robotiq_2f_85_left_driver"/>
    <axis xyz="1 0 0"/>
    <limit effort="176" lower="0.0" upper="0.872664444444" velocity="1.91986177778"/>
    <mimic joint="robotiq_2f_85_right_driver_joint" multiplier="1"/>
  </joint>
  <link name="robotiq_2f_85_left_driver">
    <inertial>
      <mass value="0.1"/>
      <origin rpy="0 0 0" xyz="0 0.02 0"/>
      <inertia ixx="0.0166666666667" ixy="0" ixz="0" iyy="0.00666666666667" iyz="0" izz="0.0166666666667"/>
    </inertial>
    <visual>
      <geometry>
        <mesh filename="package://robotiq_2f_85_gripper_visualization/meshes/visual/driver.dae" scale="0.001 0.001 0.001"/>
      </geometry>
    </visual>
    <collision>
      <origin rpy="-0.1 0 0" xyz="0 0.01 0"/>
      <geometry>
        <box size="0.002 0.004 0.002"/>
      </geometry>
    </collision>
  </link>
  <joint name="robotiq_2f_85_left_coupler_joint" type="fixed">
    <origin rpy="0 0 0" xyz="0 0.0315 -0.0041"/>
    <parent link="robotiq_2f_85_left_driver"/>
    <child link="robotiq_2f_85_left_coupler"/>
  </joint>
  <link name="robotiq_2f_85_left_coupler">
    <inertial>
      <mass value="0.1"/>
      <origin rpy="-1.7 0 0" xyz="0 0.0 0.025"/>
      <inertia ixx="0.0385416666667" ixy="0" ixz="0" iyy="0.0108333333333" iyz="0" izz="0.0427083333333"/>
    </inertial>
    <visual>
      <geometry>
        <mesh filename="package://robotiq_2f_85_gripper_visualization/meshes/visual/coupler.dae" scale="0.001 0.001 0.001"/>
      </geometry>
    </visual>
    <collision>
      <origin rpy="-1.7 0 0" xyz="0 0.0 0.025"/>
      <geometry>
        <box size="0.03 0.065 0.02"/>
      </geometry>
    </collision>
  </link>
  <joint name="robotiq_2f_85_left_follower_joint" type="revolute">
    <origin rpy="0 0 0" xyz="0 0.0061 0.0471"/>
    <parent link="robotiq_2f_85_left_coupler"/>
    <child link="robotiq_2f_85_left_follower"/>
    <axis xyz="1 0 0"/>
    <limit effort="176" lower="-2.96705911111" upper="2.96705911111" velocity="1.91986177778"/>
    <mimic joint="robotiq_2f_85_right_driver_joint" multiplier="-1"/>
  </joint>
  <link name="robotiq_2f_85_left_follower">
    <inertial>
      <mass value="0.1"/>
      <origin xyz="0 -0.018 0.022"/>
      <inertia ixx="0.021075" ixy="0" ixz="0" iyy="0.0225333333333" iyz="0" izz="0.00520833333333"/>
    </inertial>
    <visual>
      <geometry>
        <mesh filename="package://robotiq_2f_85_gripper_visualization/meshes/visual/follower.dae" scale="0.001 0.001 0.001"/>
      </geometry>
    </visual>
    <collision>
      <origin rpy="0 0 0" xyz="0 -0.01 0.022"/>
      <geometry>
        <box size="0.002 0.0015 0.0048"/>
      </geometry>
    </collision>
  </link>
  <joint name="robotiq_2f_85_left_pad_joint" type="revolute">
    <parent link="robotiq_2f_85_left_follower"/>
    <child link="robotiq_2f_85_left_pad"/>
    <axis xyz="0 0 1"/>
    <limit effort="200" lower="0" upper="0" velocity="0"/>
    <mimic joint="robotiq_2f_85_right_driver_joint" multiplier="0"/>
  </joint>
  <link name="robotiq_2f_85_left_pad">
    <inertial>
      <mass value="0.1"/>
      <origin xyz="0 -0.022 0.031"/>
      <inertia ixx="0.0113333333333" ixy="0" ixz="0" iyy="0.0141333333333" iyz="0" izz="0.00386666666667"/>
    </inertial>
    <visual>
      <geometry>
        <mesh filename="package://robotiq_2f_85_gripper_visualization/meshes/visual/pad.dae" scale="0.001 0.001 0.001"/>
      </geometry>
    </visual>
    <collision>
      <origin rpy="0 0 0" xyz="0 -0.022 0.031"/>
      <geometry>
        <box size="0.02 0.008 0.036"/>
      </geometry>
    </collision>
  </link>
  <joint name="robotiq_2f_85_left_spring_link_joint" type="revolute">
    <origin rpy="0 0 3.141592653589793" xyz="0 -0.012 0.0614"/>
    <parent link="robotiq_2f_85_base"/>
    <child link="robotiq_2f_85_left_spring_link"/>
    <axis xyz="1 0 0"/>
    <limit effort="176" lower="-2.96705911111" upper="2.96705911111" velocity="1.91986177778"/>
    <mimic joint="robotiq_2f_85_right_driver_joint" multiplier="1"/>
  </joint>
  <link name="robotiq_2f_85_left_spring_link">
    <inertial>
      <mass value="0.1"/>
      <origin rpy="-0.7068 0 0" xyz="0 0.018 0.018"/>
      <inertia ixx="0.0385416666667" ixy="0" ixz="0" iyy="0.0485416666667" iyz="0" izz="0.0166666666667"/>
    </inertial>
    <visual>
      <geometry>
        <mesh filename="package://robotiq_2f_85_gripper_visualization/meshes/visual/spring_link.dae" scale="0.001 0.001 0.001"/>
      </geometry>
    </visual>
    <collision>
      <origin rpy="-0.7068 0 0" xyz="0 0.025 0.015"/>
      <geometry>
        <box size="0.004 0.002 0.0065"/>
      </geometry>
    </collision>
  </link>
  <gazebo reference="robotiq_2f_85_right_pad">
    <kp>1000000.0</kp>
    <kd>1.0</kd>
    <mu1>100.0</mu1>
    <mu2>100.0</mu2>
    <minDepth>0.003</minDepth>
  </gazebo>
  <gazebo reference="robotiq_2f_85_left_pad">
    <kp>1000000.0</kp>
    <kd>1.0</kd>
    <mu1>100.0</mu1>
    <mu2>100.0</mu2>
    <minDepth>0.003</minDepth>
  </gazebo>
  <gazebo>
    <gripper name="grasping">
      <grasp_check>
        <attach_steps>1</attach_steps>
        <detach_steps>1</detach_steps>
        <min_contact_count>1</min_contact_count>
      </grasp_check>
      <gripper_link>robotiq_2f_85_left_pad</gripper_link>
      <palm_link>robotiq_2f_85_right_pad</palm_link>
    </gripper>
  </gazebo>
  <gazebo reference="robotiq_2f_85_right_driver_joint">
    <implicitSpringDamper>1</implicitSpringDamper>
  </gazebo>
  <gazebo reference="robotiq_2f_85_right_coupler_joint">
    <implicitSpringDamper>1</implicitSpringDamper>
  </gazebo>
  <gazebo reference="robotiq_2f_85_right_follower_joint">
    <implicitSpringDamper>1</implicitSpringDamper>
  </gazebo>
  <gazebo reference="robotiq_2f_85_right_pad_joint">
    <implicitSpringDamper>1</implicitSpringDamper>
  </gazebo>
  <gazebo reference="robotiq_2f_85_right_spring_link_joint">
    <implicitSpringDamper>1</implicitSpringDamper>
  </gazebo>
  <gazebo reference="robotiq_2f_85_left_driver_joint">
    <implicitSpringDamper>1</implicitSpringDamper>
  </gazebo>
  <gazebo reference="robotiq_2f_85_left_coupler_joint">
    <implicitSpringDamper>1</implicitSpringDamper>
  </gazebo>
  <gazebo reference="robotiq_2f_85_left_follower_joint">
    <implicitSpringDamper>1</implicitSpringDamper>
  </gazebo>
  <gazebo reference="robotiq_2f_85_left_pad_joint">
    <implicitSpringDamper>1</implicitSpringDamper>
  </gazebo>
  <gazebo reference="robotiq_2f_85_left_spring_link_joint">
    <implicitSpringDamper>1</implicitSpringDamper>
  </gazebo>
  <transmission name="robotiq_2f_85_right_driver_trans">
    <type>transmission_interface/SimpleTransmission</type>
    <joint name="robotiq_2f_85_right_driver_joint">
      <hardwareInterface>hardware_interface/PositionJointInterface</hardwareInterface>
    </joint>
    <actuator name="robotiq_2f_85_right_driver_motor">
      <hardwareInterface>hardware_interface/PositionJointInterface</hardwareInterface>
      <mechanicalReduction>1</mechanicalReduction>
    </actuator>
  </transmission>
  <gazebo>
    <plugin filename="libroboticsgroup_gazebo_mimic_joint_plugin.so" name="robotiq_2f_85_right_follower_joint_plugin">
      <joint>robotiq_2f_85_right_driver_joint</joint>
      <mimicJoint>robotiq_2f_85_right_follower_joint</mimicJoint>
      <multiplier>-1</multiplier>
    </plugin>
    <plugin filename="libroboticsgroup_gazebo_mimic_joint_plugin.so" name="robotiq_2f_85_right_spring_link_joint_plugin">
      <joint>robotiq_2f_85_right_driver_joint</joint>
      <mimicJoint>robotiq_2f_85_right_spring_link_joint</mimicJoint>
      <multiplier>1</multiplier>
    </plugin>
    <plugin filename="libroboticsgroup_gazebo_mimic_joint_plugin.so" name="robotiq_2f_85_left_follower_joint_plugin">
      <joint>robotiq_2f_85_right_driver_joint</joint>
      <mimicJoint>robotiq_2f_85_left_follower_joint</mimicJoint>
      <multiplier>-1</multiplier>
    </plugin>
    <plugin filename="libroboticsgroup_gazebo_mimic_joint_plugin.so" name="robotiq_2f_85_left_spring_link_joint_plugin">
      <joint>robotiq_2f_85_right_driver_joint</joint>
      <mimicJoint>robotiq_2f_85_left_spring_link_joint</mimicJoint>
      <multiplier>1</multiplier>
    </plugin>
    <plugin filename="libroboticsgroup_gazebo_mimic_joint_plugin.so" name="robotiq_2f_85_left_driver_joint_plugin">
      <joint>robotiq_2f_85_right_driver_joint</joint>
      <mimicJoint>robotiq_2f_85_left_driver_joint</mimicJoint>
      <multiplier>1</multiplier>
    </plugin>
    <plugin filename="libroboticsgroup_gazebo_mimic_joint_plugin.so" name="robotiq_2f_85_right_pad_joint_plugin">
      <joint>robotiq_2f_85_right_pad_joint</joint>
      <mimicJoint>robotiq_2f_85_right_follower_joint</mimicJoint>
      <multiplier>0</multiplier>
    </plugin>
    <plugin filename="libroboticsgroup_gazebo_mimic_joint_plugin.so" name="robotiq_2f_85_left_pad_joint_plugin">
      <joint>robotiq_2f_85_left_pad_joint</joint>
      <mimicJoint>robotiq_2f_85_right_follower_joint</mimicJoint>
      <multiplier>0</multiplier>
    </plugin>
  </gazebo>
</robot>
